[2021-04-25 11:36:00,657] {taskinstance.py:877} INFO - Dependencies all met for <TaskInstance: file_sensor_dag.file_sensor_task 2021-04-25T11:35:00+00:00 [queued]>
[2021-04-25 11:36:00,693] {taskinstance.py:877} INFO - Dependencies all met for <TaskInstance: file_sensor_dag.file_sensor_task 2021-04-25T11:35:00+00:00 [queued]>
[2021-04-25 11:36:00,694] {taskinstance.py:1068} INFO - 
--------------------------------------------------------------------------------
[2021-04-25 11:36:00,694] {taskinstance.py:1069} INFO - Starting attempt 1 of 3
[2021-04-25 11:36:00,694] {taskinstance.py:1070} INFO - 
--------------------------------------------------------------------------------
[2021-04-25 11:36:00,709] {taskinstance.py:1089} INFO - Executing <Task(FileSensor): file_sensor_task> on 2021-04-25T11:35:00+00:00
[2021-04-25 11:36:00,715] {standard_task_runner.py:52} INFO - Started process 125 to run task
[2021-04-25 11:36:00,724] {standard_task_runner.py:76} INFO - Running: ['airflow', 'tasks', 'run', 'file_sensor_dag', 'file_sensor_task', '2021-04-25T11:35:00+00:00', '--job-id', '872', '--pool', 'default_pool', '--raw', '--subdir', 'DAGS_FOLDER/sensor/file_sensor.py', '--cfg-path', '/tmp/tmpo7gd5mw9', '--error-file', '/tmp/tmp75z6wffc']
[2021-04-25 11:36:00,724] {standard_task_runner.py:77} INFO - Job 872: Subtask file_sensor_task
[2021-04-25 11:36:00,812] {logging_mixin.py:104} INFO - Running <TaskInstance: file_sensor_dag.file_sensor_task 2021-04-25T11:35:00+00:00 [running]> on host d6e2455ef0ec
[2021-04-25 11:36:00,880] {taskinstance.py:1283} INFO - Exporting the following env vars:
AIRFLOW_CTX_DAG_OWNER=airflow
AIRFLOW_CTX_DAG_ID=file_sensor_dag
AIRFLOW_CTX_TASK_ID=file_sensor_task
AIRFLOW_CTX_EXECUTION_DATE=2021-04-25T11:35:00+00:00
AIRFLOW_CTX_DAG_RUN_ID=scheduled__2021-04-25T11:35:00+00:00
[2021-04-25 11:36:00,907] {filesystem.py:56} INFO - Poking for file /opt/airflow/dags/python_operator/todo.json
[2021-04-25 11:38:42,264] {local_task_job.py:188} WARNING - State of this instance has been externally set to None. Terminating instance.
[2021-04-25 11:38:42,268] {process_utils.py:100} INFO - Sending Signals.SIGTERM to GPID 125
[2021-04-25 11:38:42,269] {taskinstance.py:1265} ERROR - Received SIGTERM. Terminating subprocesses.
[2021-04-25 11:38:42,291] {taskinstance.py:1482} ERROR - Task failed with exception
Traceback (most recent call last):
  File "/home/airflow/.local/lib/python3.6/site-packages/airflow/models/taskinstance.py", line 1138, in _run_raw_task
    self._prepare_and_execute_task_with_callbacks(context, task)
  File "/home/airflow/.local/lib/python3.6/site-packages/airflow/models/taskinstance.py", line 1311, in _prepare_and_execute_task_with_callbacks
    result = self._execute_task(context, task_copy)
  File "/home/airflow/.local/lib/python3.6/site-packages/airflow/models/taskinstance.py", line 1341, in _execute_task
    result = task_copy.execute(context=context)
  File "/home/airflow/.local/lib/python3.6/site-packages/airflow/sensors/base.py", line 243, in execute
    time.sleep(self._get_next_poke_interval(started_at, run_duration, try_number))
  File "/home/airflow/.local/lib/python3.6/site-packages/airflow/models/taskinstance.py", line 1267, in signal_handler
    raise AirflowException("Task received SIGTERM signal")
airflow.exceptions.AirflowException: Task received SIGTERM signal
[2021-04-25 11:38:42,305] {taskinstance.py:1532} INFO - Marking task as UP_FOR_RETRY. dag_id=file_sensor_dag, task_id=file_sensor_task, execution_date=20210425T113500, start_date=20210425T113600, end_date=20210425T113842
[2021-04-25 11:38:42,403] {process_utils.py:66} INFO - Process psutil.Process(pid=125, status='terminated', exitcode=1, started='11:36:00') (125) terminated with exit code 1
