[2021-04-25 09:50:32,429] {taskinstance.py:877} INFO - Dependencies all met for <TaskInstance: file_sensor_dag.file_sensor_task 2021-04-24T00:00:00+00:00 [queued]>
[2021-04-25 09:50:32,448] {taskinstance.py:877} INFO - Dependencies all met for <TaskInstance: file_sensor_dag.file_sensor_task 2021-04-24T00:00:00+00:00 [queued]>
[2021-04-25 09:50:32,448] {taskinstance.py:1068} INFO - 
--------------------------------------------------------------------------------
[2021-04-25 09:50:32,448] {taskinstance.py:1069} INFO - Starting attempt 1 of 3
[2021-04-25 09:50:32,448] {taskinstance.py:1070} INFO - 
--------------------------------------------------------------------------------
[2021-04-25 09:50:32,462] {taskinstance.py:1089} INFO - Executing <Task(FileSensor): file_sensor_task> on 2021-04-24T00:00:00+00:00
[2021-04-25 09:50:32,466] {standard_task_runner.py:52} INFO - Started process 65 to run task
[2021-04-25 09:50:32,470] {standard_task_runner.py:76} INFO - Running: ['airflow', 'tasks', 'run', 'file_sensor_dag', 'file_sensor_task', '2021-04-24T00:00:00+00:00', '--job-id', '828', '--pool', 'default_pool', '--raw', '--subdir', 'DAGS_FOLDER/sensor/simple_sensor_dag.py', '--cfg-path', '/tmp/tmpunr2npqy', '--error-file', '/tmp/tmpbibkvclu']
[2021-04-25 09:50:32,471] {standard_task_runner.py:77} INFO - Job 828: Subtask file_sensor_task
[2021-04-25 09:50:32,531] {logging_mixin.py:104} INFO - Running <TaskInstance: file_sensor_dag.file_sensor_task 2021-04-24T00:00:00+00:00 [running]> on host d6e2455ef0ec
[2021-04-25 09:50:32,583] {taskinstance.py:1283} INFO - Exporting the following env vars:
AIRFLOW_CTX_DAG_OWNER=airflow
AIRFLOW_CTX_DAG_ID=file_sensor_dag
AIRFLOW_CTX_TASK_ID=file_sensor_task
AIRFLOW_CTX_EXECUTION_DATE=2021-04-24T00:00:00+00:00
AIRFLOW_CTX_DAG_RUN_ID=scheduled__2021-04-24T00:00:00+00:00
[2021-04-25 09:50:32,611] {taskinstance.py:1482} ERROR - Task failed with exception
Traceback (most recent call last):
  File "/home/airflow/.local/lib/python3.6/site-packages/airflow/models/taskinstance.py", line 1138, in _run_raw_task
    self._prepare_and_execute_task_with_callbacks(context, task)
  File "/home/airflow/.local/lib/python3.6/site-packages/airflow/models/taskinstance.py", line 1311, in _prepare_and_execute_task_with_callbacks
    result = self._execute_task(context, task_copy)
  File "/home/airflow/.local/lib/python3.6/site-packages/airflow/models/taskinstance.py", line 1341, in _execute_task
    result = task_copy.execute(context=context)
  File "/home/airflow/.local/lib/python3.6/site-packages/airflow/sensors/base.py", line 228, in execute
    while not self.poke(context):
  File "/home/airflow/.local/lib/python3.6/site-packages/airflow/sensors/filesystem.py", line 53, in poke
    hook = FSHook(self.fs_conn_id)
  File "/home/airflow/.local/lib/python3.6/site-packages/airflow/hooks/filesystem.py", line 38, in __init__
    conn = self.get_connection(conn_id)
  File "/home/airflow/.local/lib/python3.6/site-packages/airflow/hooks/base.py", line 67, in get_connection
    conn = Connection.get_connection_from_secrets(conn_id)
  File "/home/airflow/.local/lib/python3.6/site-packages/airflow/models/connection.py", line 354, in get_connection_from_secrets
    raise AirflowNotFoundException(f"The conn_id `{conn_id}` isn't defined")
airflow.exceptions.AirflowNotFoundException: The conn_id `fs_default` isn't defined
[2021-04-25 09:50:32,614] {taskinstance.py:1532} INFO - Marking task as UP_FOR_RETRY. dag_id=file_sensor_dag, task_id=file_sensor_task, execution_date=20210424T000000, start_date=20210425T095032, end_date=20210425T095032
[2021-04-25 09:50:32,645] {local_task_job.py:146} INFO - Task exited with return code 1
[2021-04-25 10:09:56,060] {taskinstance.py:877} INFO - Dependencies all met for <TaskInstance: file_sensor_dag.file_sensor_task 2021-04-24T00:00:00+00:00 [queued]>
[2021-04-25 10:09:56,088] {taskinstance.py:877} INFO - Dependencies all met for <TaskInstance: file_sensor_dag.file_sensor_task 2021-04-24T00:00:00+00:00 [queued]>
[2021-04-25 10:09:56,089] {taskinstance.py:1068} INFO - 
--------------------------------------------------------------------------------
[2021-04-25 10:09:56,089] {taskinstance.py:1069} INFO - Starting attempt 1 of 3
[2021-04-25 10:09:56,089] {taskinstance.py:1070} INFO - 
--------------------------------------------------------------------------------
[2021-04-25 10:09:56,104] {taskinstance.py:1089} INFO - Executing <Task(FileSensor): file_sensor_task> on 2021-04-24T00:00:00+00:00
[2021-04-25 10:09:56,109] {standard_task_runner.py:52} INFO - Started process 55 to run task
[2021-04-25 10:09:56,117] {standard_task_runner.py:76} INFO - Running: ['airflow', 'tasks', 'run', 'file_sensor_dag', 'file_sensor_task', '2021-04-24T00:00:00+00:00', '--job-id', '837', '--pool', 'default_pool', '--raw', '--subdir', 'DAGS_FOLDER/sensor/file_sensor.py', '--cfg-path', '/tmp/tmpgjz91h02', '--error-file', '/tmp/tmp7w_0fzv_']
[2021-04-25 10:09:56,118] {standard_task_runner.py:77} INFO - Job 837: Subtask file_sensor_task
[2021-04-25 10:09:56,187] {logging_mixin.py:104} INFO - Running <TaskInstance: file_sensor_dag.file_sensor_task 2021-04-24T00:00:00+00:00 [running]> on host d6e2455ef0ec
[2021-04-25 10:09:56,246] {taskinstance.py:1283} INFO - Exporting the following env vars:
AIRFLOW_CTX_DAG_OWNER=airflow
AIRFLOW_CTX_DAG_ID=file_sensor_dag
AIRFLOW_CTX_TASK_ID=file_sensor_task
AIRFLOW_CTX_EXECUTION_DATE=2021-04-24T00:00:00+00:00
AIRFLOW_CTX_DAG_RUN_ID=scheduled__2021-04-24T00:00:00+00:00
[2021-04-25 10:09:56,277] {taskinstance.py:1482} ERROR - Task failed with exception
Traceback (most recent call last):
  File "/home/airflow/.local/lib/python3.6/site-packages/airflow/models/taskinstance.py", line 1138, in _run_raw_task
    self._prepare_and_execute_task_with_callbacks(context, task)
  File "/home/airflow/.local/lib/python3.6/site-packages/airflow/models/taskinstance.py", line 1311, in _prepare_and_execute_task_with_callbacks
    result = self._execute_task(context, task_copy)
  File "/home/airflow/.local/lib/python3.6/site-packages/airflow/models/taskinstance.py", line 1341, in _execute_task
    result = task_copy.execute(context=context)
  File "/home/airflow/.local/lib/python3.6/site-packages/airflow/sensors/base.py", line 228, in execute
    while not self.poke(context):
  File "/home/airflow/.local/lib/python3.6/site-packages/airflow/sensors/filesystem.py", line 53, in poke
    hook = FSHook(self.fs_conn_id)
  File "/home/airflow/.local/lib/python3.6/site-packages/airflow/hooks/filesystem.py", line 38, in __init__
    conn = self.get_connection(conn_id)
  File "/home/airflow/.local/lib/python3.6/site-packages/airflow/hooks/base.py", line 67, in get_connection
    conn = Connection.get_connection_from_secrets(conn_id)
  File "/home/airflow/.local/lib/python3.6/site-packages/airflow/models/connection.py", line 354, in get_connection_from_secrets
    raise AirflowNotFoundException(f"The conn_id `{conn_id}` isn't defined")
airflow.exceptions.AirflowNotFoundException: The conn_id `fs_default` isn't defined
[2021-04-25 10:09:56,281] {taskinstance.py:1532} INFO - Marking task as UP_FOR_RETRY. dag_id=file_sensor_dag, task_id=file_sensor_task, execution_date=20210424T000000, start_date=20210425T100956, end_date=20210425T100956
[2021-04-25 10:09:56,333] {local_task_job.py:146} INFO - Task exited with return code 1
