[2021-04-25 09:55:33,156] {taskinstance.py:877} INFO - Dependencies all met for <TaskInstance: file_sensor_dag.file_sensor_task 2021-04-24T00:00:00+00:00 [queued]>
[2021-04-25 09:55:33,173] {taskinstance.py:877} INFO - Dependencies all met for <TaskInstance: file_sensor_dag.file_sensor_task 2021-04-24T00:00:00+00:00 [queued]>
[2021-04-25 09:55:33,174] {taskinstance.py:1068} INFO - 
--------------------------------------------------------------------------------
[2021-04-25 09:55:33,174] {taskinstance.py:1069} INFO - Starting attempt 2 of 3
[2021-04-25 09:55:33,174] {taskinstance.py:1070} INFO - 
--------------------------------------------------------------------------------
[2021-04-25 09:55:33,191] {taskinstance.py:1089} INFO - Executing <Task(FileSensor): file_sensor_task> on 2021-04-24T00:00:00+00:00
[2021-04-25 09:55:33,195] {standard_task_runner.py:52} INFO - Started process 73 to run task
[2021-04-25 09:55:33,199] {standard_task_runner.py:76} INFO - Running: ['airflow', 'tasks', 'run', 'file_sensor_dag', 'file_sensor_task', '2021-04-24T00:00:00+00:00', '--job-id', '832', '--pool', 'default_pool', '--raw', '--subdir', 'DAGS_FOLDER/sensor/simple_sensor_dag.py', '--cfg-path', '/tmp/tmp9owufw7g', '--error-file', '/tmp/tmphc9tj3c5']
[2021-04-25 09:55:33,200] {standard_task_runner.py:77} INFO - Job 832: Subtask file_sensor_task
[2021-04-25 09:55:33,253] {logging_mixin.py:104} INFO - Running <TaskInstance: file_sensor_dag.file_sensor_task 2021-04-24T00:00:00+00:00 [running]> on host d6e2455ef0ec
[2021-04-25 09:55:33,295] {taskinstance.py:1283} INFO - Exporting the following env vars:
AIRFLOW_CTX_DAG_OWNER=airflow
AIRFLOW_CTX_DAG_ID=file_sensor_dag
AIRFLOW_CTX_TASK_ID=file_sensor_task
AIRFLOW_CTX_EXECUTION_DATE=2021-04-24T00:00:00+00:00
AIRFLOW_CTX_DAG_RUN_ID=scheduled__2021-04-24T00:00:00+00:00
[2021-04-25 09:55:33,320] {taskinstance.py:1482} ERROR - Task failed with exception
Traceback (most recent call last):
  File "/home/airflow/.local/lib/python3.6/site-packages/airflow/models/taskinstance.py", line 1138, in _run_raw_task
    self._prepare_and_execute_task_with_callbacks(context, task)
  File "/home/airflow/.local/lib/python3.6/site-packages/airflow/models/taskinstance.py", line 1311, in _prepare_and_execute_task_with_callbacks
    result = self._execute_task(context, task_copy)
  File "/home/airflow/.local/lib/python3.6/site-packages/airflow/models/taskinstance.py", line 1341, in _execute_task
    result = task_copy.execute(context=context)
  File "/home/airflow/.local/lib/python3.6/site-packages/airflow/sensors/base.py", line 228, in execute
    while not self.poke(context):
  File "/home/airflow/.local/lib/python3.6/site-packages/airflow/sensors/filesystem.py", line 53, in poke
    hook = FSHook(self.fs_conn_id)
  File "/home/airflow/.local/lib/python3.6/site-packages/airflow/hooks/filesystem.py", line 38, in __init__
    conn = self.get_connection(conn_id)
  File "/home/airflow/.local/lib/python3.6/site-packages/airflow/hooks/base.py", line 67, in get_connection
    conn = Connection.get_connection_from_secrets(conn_id)
  File "/home/airflow/.local/lib/python3.6/site-packages/airflow/models/connection.py", line 354, in get_connection_from_secrets
    raise AirflowNotFoundException(f"The conn_id `{conn_id}` isn't defined")
airflow.exceptions.AirflowNotFoundException: The conn_id `fs_default` isn't defined
[2021-04-25 09:55:33,323] {taskinstance.py:1532} INFO - Marking task as UP_FOR_RETRY. dag_id=file_sensor_dag, task_id=file_sensor_task, execution_date=20210424T000000, start_date=20210425T095533, end_date=20210425T095533
[2021-04-25 09:55:33,374] {local_task_job.py:146} INFO - Task exited with return code 1
[2021-04-25 10:14:57,471] {taskinstance.py:877} INFO - Dependencies all met for <TaskInstance: file_sensor_dag.file_sensor_task 2021-04-24T00:00:00+00:00 [queued]>
[2021-04-25 10:14:57,497] {taskinstance.py:877} INFO - Dependencies all met for <TaskInstance: file_sensor_dag.file_sensor_task 2021-04-24T00:00:00+00:00 [queued]>
[2021-04-25 10:14:57,497] {taskinstance.py:1068} INFO - 
--------------------------------------------------------------------------------
[2021-04-25 10:14:57,497] {taskinstance.py:1069} INFO - Starting attempt 2 of 3
[2021-04-25 10:14:57,497] {taskinstance.py:1070} INFO - 
--------------------------------------------------------------------------------
[2021-04-25 10:14:57,511] {taskinstance.py:1089} INFO - Executing <Task(FileSensor): file_sensor_task> on 2021-04-24T00:00:00+00:00
[2021-04-25 10:14:57,518] {standard_task_runner.py:52} INFO - Started process 59 to run task
[2021-04-25 10:14:57,523] {standard_task_runner.py:76} INFO - Running: ['airflow', 'tasks', 'run', 'file_sensor_dag', 'file_sensor_task', '2021-04-24T00:00:00+00:00', '--job-id', '839', '--pool', 'default_pool', '--raw', '--subdir', 'DAGS_FOLDER/sensor/file_sensor.py', '--cfg-path', '/tmp/tmp1rii8_zi', '--error-file', '/tmp/tmpjfc5xn18']
[2021-04-25 10:14:57,525] {standard_task_runner.py:77} INFO - Job 839: Subtask file_sensor_task
[2021-04-25 10:14:57,580] {logging_mixin.py:104} INFO - Running <TaskInstance: file_sensor_dag.file_sensor_task 2021-04-24T00:00:00+00:00 [running]> on host d6e2455ef0ec
[2021-04-25 10:14:57,624] {taskinstance.py:1283} INFO - Exporting the following env vars:
AIRFLOW_CTX_DAG_OWNER=airflow
AIRFLOW_CTX_DAG_ID=file_sensor_dag
AIRFLOW_CTX_TASK_ID=file_sensor_task
AIRFLOW_CTX_EXECUTION_DATE=2021-04-24T00:00:00+00:00
AIRFLOW_CTX_DAG_RUN_ID=scheduled__2021-04-24T00:00:00+00:00
[2021-04-25 10:14:57,644] {taskinstance.py:1482} ERROR - Task failed with exception
Traceback (most recent call last):
  File "/home/airflow/.local/lib/python3.6/site-packages/airflow/models/taskinstance.py", line 1138, in _run_raw_task
    self._prepare_and_execute_task_with_callbacks(context, task)
  File "/home/airflow/.local/lib/python3.6/site-packages/airflow/models/taskinstance.py", line 1311, in _prepare_and_execute_task_with_callbacks
    result = self._execute_task(context, task_copy)
  File "/home/airflow/.local/lib/python3.6/site-packages/airflow/models/taskinstance.py", line 1341, in _execute_task
    result = task_copy.execute(context=context)
  File "/home/airflow/.local/lib/python3.6/site-packages/airflow/sensors/base.py", line 228, in execute
    while not self.poke(context):
  File "/home/airflow/.local/lib/python3.6/site-packages/airflow/sensors/filesystem.py", line 53, in poke
    hook = FSHook(self.fs_conn_id)
  File "/home/airflow/.local/lib/python3.6/site-packages/airflow/hooks/filesystem.py", line 38, in __init__
    conn = self.get_connection(conn_id)
  File "/home/airflow/.local/lib/python3.6/site-packages/airflow/hooks/base.py", line 67, in get_connection
    conn = Connection.get_connection_from_secrets(conn_id)
  File "/home/airflow/.local/lib/python3.6/site-packages/airflow/models/connection.py", line 354, in get_connection_from_secrets
    raise AirflowNotFoundException(f"The conn_id `{conn_id}` isn't defined")
airflow.exceptions.AirflowNotFoundException: The conn_id `fs_default` isn't defined
[2021-04-25 10:14:57,647] {taskinstance.py:1532} INFO - Marking task as UP_FOR_RETRY. dag_id=file_sensor_dag, task_id=file_sensor_task, execution_date=20210424T000000, start_date=20210425T101457, end_date=20210425T101457
[2021-04-25 10:14:57,699] {local_task_job.py:146} INFO - Task exited with return code 1
