[2021-04-25 08:05:53,842] {taskinstance.py:877} INFO - Dependencies all met for <TaskInstance: send_email_dag.send_email_task 2021-04-24T00:00:00+00:00 [queued]>
[2021-04-25 08:05:53,876] {taskinstance.py:877} INFO - Dependencies all met for <TaskInstance: send_email_dag.send_email_task 2021-04-24T00:00:00+00:00 [queued]>
[2021-04-25 08:05:53,877] {taskinstance.py:1068} INFO - 
--------------------------------------------------------------------------------
[2021-04-25 08:05:53,877] {taskinstance.py:1069} INFO - Starting attempt 1 of 3
[2021-04-25 08:05:53,878] {taskinstance.py:1070} INFO - 
--------------------------------------------------------------------------------
[2021-04-25 08:05:53,917] {taskinstance.py:1089} INFO - Executing <Task(EmailOperator): send_email_task> on 2021-04-24T00:00:00+00:00
[2021-04-25 08:05:53,936] {standard_task_runner.py:76} INFO - Running: ['airflow', 'tasks', 'run', 'send_email_dag', 'send_email_task', '2021-04-24T00:00:00+00:00', '--job-id', '790', '--pool', 'default_pool', '--raw', '--subdir', 'DAGS_FOLDER/email_operator/send_email.py', '--cfg-path', '/tmp/tmpkftesj6x', '--error-file', '/tmp/tmp576vtcyo']
[2021-04-25 08:05:53,925] {standard_task_runner.py:52} INFO - Started process 61 to run task
[2021-04-25 08:05:53,941] {standard_task_runner.py:77} INFO - Job 790: Subtask send_email_task
[2021-04-25 08:05:54,088] {logging_mixin.py:104} INFO - Running <TaskInstance: send_email_dag.send_email_task 2021-04-24T00:00:00+00:00 [running]> on host d6e2455ef0ec
[2021-04-25 08:05:54,194] {taskinstance.py:1283} INFO - Exporting the following env vars:
AIRFLOW_CTX_DAG_OWNER=airflow
AIRFLOW_CTX_DAG_ID=send_email_dag
AIRFLOW_CTX_TASK_ID=send_email_task
AIRFLOW_CTX_EXECUTION_DATE=2021-04-24T00:00:00+00:00
AIRFLOW_CTX_DAG_RUN_ID=scheduled__2021-04-24T00:00:00+00:00
[2021-04-25 08:05:54,203] {taskinstance.py:1482} ERROR - Task failed with exception
Traceback (most recent call last):
  File "/home/airflow/.local/lib/python3.6/site-packages/airflow/models/taskinstance.py", line 1138, in _run_raw_task
    self._prepare_and_execute_task_with_callbacks(context, task)
  File "/home/airflow/.local/lib/python3.6/site-packages/airflow/models/taskinstance.py", line 1311, in _prepare_and_execute_task_with_callbacks
    result = self._execute_task(context, task_copy)
  File "/home/airflow/.local/lib/python3.6/site-packages/airflow/models/taskinstance.py", line 1341, in _execute_task
    result = task_copy.execute(context=context)
  File "/home/airflow/.local/lib/python3.6/site-packages/airflow/operators/email.py", line 87, in execute
    mime_charset=self.mime_charset,
  File "/home/airflow/.local/lib/python3.6/site-packages/airflow/utils/email.py", line 62, in send_email
    **kwargs,
  File "/home/airflow/.local/lib/python3.6/site-packages/airflow/utils/email.py", line 94, in send_email_smtp
    mime_charset=mime_charset,
  File "/home/airflow/.local/lib/python3.6/site-packages/airflow/utils/email.py", line 152, in build_mime_message
    with open(fname, "rb") as file:
FileNotFoundError: [Errno 2] No such file or directory: 't'
[2021-04-25 08:05:54,211] {taskinstance.py:1532} INFO - Marking task as UP_FOR_RETRY. dag_id=send_email_dag, task_id=send_email_task, execution_date=20210424T000000, start_date=20210425T080553, end_date=20210425T080554
[2021-04-25 08:05:54,279] {local_task_job.py:146} INFO - Task exited with return code 1
