[2021-04-25 10:44:52,841] {taskinstance.py:877} INFO - Dependencies all met for <TaskInstance: external_sensor_dag.external_sensor_task 2021-04-25T10:44:51.964683+00:00 [queued]>
[2021-04-25 10:44:52,877] {taskinstance.py:877} INFO - Dependencies all met for <TaskInstance: external_sensor_dag.external_sensor_task 2021-04-25T10:44:51.964683+00:00 [queued]>
[2021-04-25 10:44:52,878] {taskinstance.py:1068} INFO - 
--------------------------------------------------------------------------------
[2021-04-25 10:44:52,878] {taskinstance.py:1069} INFO - Starting attempt 1 of 3
[2021-04-25 10:44:52,878] {taskinstance.py:1070} INFO - 
--------------------------------------------------------------------------------
[2021-04-25 10:44:52,899] {taskinstance.py:1089} INFO - Executing <Task(ExternalTaskSensor): external_sensor_task> on 2021-04-25T10:44:51.964683+00:00
[2021-04-25 10:44:52,903] {standard_task_runner.py:52} INFO - Started process 81 to run task
[2021-04-25 10:44:52,912] {standard_task_runner.py:76} INFO - Running: ['airflow', 'tasks', 'run', 'external_sensor_dag', 'external_sensor_task', '2021-04-25T10:44:51.964683+00:00', '--job-id', '850', '--pool', 'default_pool', '--raw', '--subdir', 'DAGS_FOLDER/sensor/external_sensor.py', '--cfg-path', '/tmp/tmpgpl204cp', '--error-file', '/tmp/tmpf6e6u4sr']
[2021-04-25 10:44:52,913] {standard_task_runner.py:77} INFO - Job 850: Subtask external_sensor_task
[2021-04-25 10:44:52,991] {logging_mixin.py:104} INFO - Running <TaskInstance: external_sensor_dag.external_sensor_task 2021-04-25T10:44:51.964683+00:00 [running]> on host d6e2455ef0ec
[2021-04-25 10:44:53,069] {taskinstance.py:1283} INFO - Exporting the following env vars:
AIRFLOW_CTX_DAG_OWNER=airflow
AIRFLOW_CTX_DAG_ID=external_sensor_dag
AIRFLOW_CTX_TASK_ID=external_sensor_task
AIRFLOW_CTX_EXECUTION_DATE=2021-04-25T10:44:51.964683+00:00
AIRFLOW_CTX_DAG_RUN_ID=manual__2021-04-25T10:44:51.964683+00:00
[2021-04-25 10:44:53,070] {external_task.py:154} INFO - Poking for write_file_python_operator.fetch_and_write_a_file_task on 2021-04-25T10:44:51.964683+00:00 ... 
[2021-04-25 10:45:53,145] {external_task.py:154} INFO - Poking for write_file_python_operator.fetch_and_write_a_file_task on 2021-04-25T10:44:51.964683+00:00 ... 
[2021-04-25 10:46:53,214] {external_task.py:154} INFO - Poking for write_file_python_operator.fetch_and_write_a_file_task on 2021-04-25T10:44:51.964683+00:00 ... 
[2021-04-25 10:47:53,286] {external_task.py:154} INFO - Poking for write_file_python_operator.fetch_and_write_a_file_task on 2021-04-25T10:44:51.964683+00:00 ... 
[2021-04-25 10:48:53,354] {external_task.py:154} INFO - Poking for write_file_python_operator.fetch_and_write_a_file_task on 2021-04-25T10:44:51.964683+00:00 ... 
[2021-04-25 10:49:53,418] {external_task.py:154} INFO - Poking for write_file_python_operator.fetch_and_write_a_file_task on 2021-04-25T10:44:51.964683+00:00 ... 
[2021-04-25 10:50:53,474] {external_task.py:154} INFO - Poking for write_file_python_operator.fetch_and_write_a_file_task on 2021-04-25T10:44:51.964683+00:00 ... 
[2021-04-25 10:51:53,544] {external_task.py:154} INFO - Poking for write_file_python_operator.fetch_and_write_a_file_task on 2021-04-25T10:44:51.964683+00:00 ... 
[2021-04-25 10:52:53,597] {external_task.py:154} INFO - Poking for write_file_python_operator.fetch_and_write_a_file_task on 2021-04-25T10:44:51.964683+00:00 ... 
[2021-04-25 10:53:53,651] {external_task.py:154} INFO - Poking for write_file_python_operator.fetch_and_write_a_file_task on 2021-04-25T10:44:51.964683+00:00 ... 
[2021-04-25 10:54:53,714] {external_task.py:154} INFO - Poking for write_file_python_operator.fetch_and_write_a_file_task on 2021-04-25T10:44:51.964683+00:00 ... 
[2021-04-25 10:55:13,809] {local_task_job.py:188} WARNING - State of this instance has been externally set to None. Terminating instance.
[2021-04-25 10:55:13,821] {process_utils.py:100} INFO - Sending Signals.SIGTERM to GPID 81
[2021-04-25 10:55:13,822] {taskinstance.py:1265} ERROR - Received SIGTERM. Terminating subprocesses.
[2021-04-25 10:55:13,839] {taskinstance.py:1482} ERROR - Task failed with exception
Traceback (most recent call last):
  File "/home/airflow/.local/lib/python3.6/site-packages/airflow/models/taskinstance.py", line 1138, in _run_raw_task
    self._prepare_and_execute_task_with_callbacks(context, task)
  File "/home/airflow/.local/lib/python3.6/site-packages/airflow/models/taskinstance.py", line 1311, in _prepare_and_execute_task_with_callbacks
    result = self._execute_task(context, task_copy)
  File "/home/airflow/.local/lib/python3.6/site-packages/airflow/models/taskinstance.py", line 1341, in _execute_task
    result = task_copy.execute(context=context)
  File "/home/airflow/.local/lib/python3.6/site-packages/airflow/sensors/base.py", line 243, in execute
    time.sleep(self._get_next_poke_interval(started_at, run_duration, try_number))
  File "/home/airflow/.local/lib/python3.6/site-packages/airflow/models/taskinstance.py", line 1267, in signal_handler
    raise AirflowException("Task received SIGTERM signal")
airflow.exceptions.AirflowException: Task received SIGTERM signal
[2021-04-25 10:55:13,848] {taskinstance.py:1532} INFO - Marking task as UP_FOR_RETRY. dag_id=external_sensor_dag, task_id=external_sensor_task, execution_date=20210425T104451, start_date=20210425T104452, end_date=20210425T105513
[2021-04-25 10:55:13,916] {process_utils.py:66} INFO - Process psutil.Process(pid=81, status='terminated', exitcode=1, started='10:44:52') (81) terminated with exit code 1
