[2021-04-25 14:14:36,268] {taskinstance.py:877} INFO - Dependencies all met for <TaskInstance: templated_bash_operator_dag.read_json_file_task 2021-04-25T14:14:34.617713+00:00 [queued]>
[2021-04-25 14:14:36,298] {taskinstance.py:877} INFO - Dependencies all met for <TaskInstance: templated_bash_operator_dag.read_json_file_task 2021-04-25T14:14:34.617713+00:00 [queued]>
[2021-04-25 14:14:36,298] {taskinstance.py:1068} INFO - 
--------------------------------------------------------------------------------
[2021-04-25 14:14:36,298] {taskinstance.py:1069} INFO - Starting attempt 1 of 3
[2021-04-25 14:14:36,298] {taskinstance.py:1070} INFO - 
--------------------------------------------------------------------------------
[2021-04-25 14:14:36,332] {taskinstance.py:1089} INFO - Executing <Task(BashOperator): read_json_file_task> on 2021-04-25T14:14:34.617713+00:00
[2021-04-25 14:14:36,345] {standard_task_runner.py:76} INFO - Running: ['airflow', 'tasks', 'run', 'templated_bash_operator_dag', 'read_json_file_task', '2021-04-25T14:14:34.617713+00:00', '--job-id', '932', '--pool', 'default_pool', '--raw', '--subdir', 'DAGS_FOLDER/bash_operator/templated_bash_operator_dag.py', '--cfg-path', '/tmp/tmp8dv0fpfj', '--error-file', '/tmp/tmpoxzl2u48']
[2021-04-25 14:14:36,337] {standard_task_runner.py:52} INFO - Started process 129 to run task
[2021-04-25 14:14:36,345] {standard_task_runner.py:77} INFO - Job 932: Subtask read_json_file_task
[2021-04-25 14:14:36,458] {logging_mixin.py:104} INFO - Running <TaskInstance: templated_bash_operator_dag.read_json_file_task 2021-04-25T14:14:34.617713+00:00 [running]> on host d6e2455ef0ec
[2021-04-25 14:14:36,512] {taskinstance.py:1482} ERROR - Task failed with exception
Traceback (most recent call last):
  File "/home/airflow/.local/lib/python3.6/site-packages/airflow/models/taskinstance.py", line 1138, in _run_raw_task
    self._prepare_and_execute_task_with_callbacks(context, task)
  File "/home/airflow/.local/lib/python3.6/site-packages/airflow/models/taskinstance.py", line 1275, in _prepare_and_execute_task_with_callbacks
    self.render_templates(context=context)
  File "/home/airflow/.local/lib/python3.6/site-packages/airflow/models/taskinstance.py", line 1779, in render_templates
    self.task.render_template_fields(context)
  File "/home/airflow/.local/lib/python3.6/site-packages/airflow/models/baseoperator.py", line 892, in render_template_fields
    self._do_render_template_fields(self, self.template_fields, context, jinja_env, set())
  File "/home/airflow/.local/lib/python3.6/site-packages/airflow/models/baseoperator.py", line 905, in _do_render_template_fields
    rendered_content = self.render_template(content, context, jinja_env, seen_oids)
  File "/home/airflow/.local/lib/python3.6/site-packages/airflow/models/baseoperator.py", line 942, in render_template
    return jinja_env.from_string(content).render(**context)
  File "/home/airflow/.local/lib/python3.6/site-packages/jinja2/environment.py", line 1090, in render
    self.environment.handle_exception()
  File "/home/airflow/.local/lib/python3.6/site-packages/jinja2/environment.py", line 832, in handle_exception
    reraise(*rewrite_traceback_stack(source=source))
  File "/home/airflow/.local/lib/python3.6/site-packages/jinja2/_compat.py", line 28, in reraise
    raise value.with_traceback(tb)
  File "<template>", line 4, in top-level template code
jinja2.exceptions.UndefinedError: 'dict object' has no attribute 'filename'
[2021-04-25 14:14:36,518] {taskinstance.py:1532} INFO - Marking task as UP_FOR_RETRY. dag_id=templated_bash_operator_dag, task_id=read_json_file_task, execution_date=20210425T141434, start_date=20210425T141436, end_date=20210425T141436
[2021-04-25 14:14:36,672] {local_task_job.py:146} INFO - Task exited with return code 1
