[2021-04-25 10:32:44,528] {taskinstance.py:877} INFO - Dependencies all met for <TaskInstance: external_sensor_dag.external_sensor_task 2021-04-25T10:32:42.968078+00:00 [queued]>
[2021-04-25 10:32:44,556] {taskinstance.py:877} INFO - Dependencies all met for <TaskInstance: external_sensor_dag.external_sensor_task 2021-04-25T10:32:42.968078+00:00 [queued]>
[2021-04-25 10:32:44,556] {taskinstance.py:1068} INFO - 
--------------------------------------------------------------------------------
[2021-04-25 10:32:44,556] {taskinstance.py:1069} INFO - Starting attempt 1 of 3
[2021-04-25 10:32:44,556] {taskinstance.py:1070} INFO - 
--------------------------------------------------------------------------------
[2021-04-25 10:32:44,574] {taskinstance.py:1089} INFO - Executing <Task(ExternalTaskSensor): external_sensor_task> on 2021-04-25T10:32:42.968078+00:00
[2021-04-25 10:32:44,581] {standard_task_runner.py:52} INFO - Started process 73 to run task
[2021-04-25 10:32:44,588] {standard_task_runner.py:76} INFO - Running: ['airflow', 'tasks', 'run', 'external_sensor_dag', 'external_sensor_task', '2021-04-25T10:32:42.968078+00:00', '--job-id', '846', '--pool', 'default_pool', '--raw', '--subdir', 'DAGS_FOLDER/sensor/external_sensor.py', '--cfg-path', '/tmp/tmpuk9nywm9', '--error-file', '/tmp/tmpcsn9p8c5']
[2021-04-25 10:32:44,589] {standard_task_runner.py:77} INFO - Job 846: Subtask external_sensor_task
[2021-04-25 10:32:44,672] {logging_mixin.py:104} INFO - Running <TaskInstance: external_sensor_dag.external_sensor_task 2021-04-25T10:32:42.968078+00:00 [running]> on host d6e2455ef0ec
[2021-04-25 10:32:44,749] {taskinstance.py:1283} INFO - Exporting the following env vars:
AIRFLOW_CTX_DAG_OWNER=airflow
AIRFLOW_CTX_DAG_ID=external_sensor_dag
AIRFLOW_CTX_TASK_ID=external_sensor_task
AIRFLOW_CTX_EXECUTION_DATE=2021-04-25T10:32:42.968078+00:00
AIRFLOW_CTX_DAG_RUN_ID=manual__2021-04-25T10:32:42.968078+00:00
[2021-04-25 10:32:44,750] {external_task.py:154} INFO - Poking for write_file_python_operator.fetch_and_write_a_file_task on 2021-04-25T10:32:42.968078+00:00 ... 
[2021-04-25 10:33:44,764] {external_task.py:154} INFO - Poking for write_file_python_operator.fetch_and_write_a_file_task on 2021-04-25T10:32:42.968078+00:00 ... 
[2021-04-25 10:34:44,837] {external_task.py:154} INFO - Poking for write_file_python_operator.fetch_and_write_a_file_task on 2021-04-25T10:32:42.968078+00:00 ... 
[2021-04-25 10:35:44,893] {external_task.py:154} INFO - Poking for write_file_python_operator.fetch_and_write_a_file_task on 2021-04-25T10:32:42.968078+00:00 ... 
[2021-04-25 10:36:44,964] {external_task.py:154} INFO - Poking for write_file_python_operator.fetch_and_write_a_file_task on 2021-04-25T10:32:42.968078+00:00 ... 
[2021-04-25 10:37:45,024] {external_task.py:154} INFO - Poking for write_file_python_operator.fetch_and_write_a_file_task on 2021-04-25T10:32:42.968078+00:00 ... 
[2021-04-25 10:38:45,049] {external_task.py:154} INFO - Poking for write_file_python_operator.fetch_and_write_a_file_task on 2021-04-25T10:32:42.968078+00:00 ... 
[2021-04-25 10:39:45,114] {external_task.py:154} INFO - Poking for write_file_python_operator.fetch_and_write_a_file_task on 2021-04-25T10:32:42.968078+00:00 ... 
[2021-04-25 10:40:45,153] {external_task.py:154} INFO - Poking for write_file_python_operator.fetch_and_write_a_file_task on 2021-04-25T10:32:42.968078+00:00 ... 
[2021-04-25 10:41:45,217] {external_task.py:154} INFO - Poking for write_file_python_operator.fetch_and_write_a_file_task on 2021-04-25T10:32:42.968078+00:00 ... 
[2021-04-25 10:42:45,241] {external_task.py:154} INFO - Poking for write_file_python_operator.fetch_and_write_a_file_task on 2021-04-25T10:32:42.968078+00:00 ... 
[2021-04-25 10:42:56,772] {local_task_job.py:188} WARNING - State of this instance has been externally set to None. Terminating instance.
[2021-04-25 10:42:56,790] {process_utils.py:100} INFO - Sending Signals.SIGTERM to GPID 73
[2021-04-25 10:42:56,791] {taskinstance.py:1265} ERROR - Received SIGTERM. Terminating subprocesses.
[2021-04-25 10:42:56,811] {taskinstance.py:1482} ERROR - Task failed with exception
Traceback (most recent call last):
  File "/home/airflow/.local/lib/python3.6/site-packages/airflow/models/taskinstance.py", line 1138, in _run_raw_task
    self._prepare_and_execute_task_with_callbacks(context, task)
  File "/home/airflow/.local/lib/python3.6/site-packages/airflow/models/taskinstance.py", line 1311, in _prepare_and_execute_task_with_callbacks
    result = self._execute_task(context, task_copy)
  File "/home/airflow/.local/lib/python3.6/site-packages/airflow/models/taskinstance.py", line 1341, in _execute_task
    result = task_copy.execute(context=context)
  File "/home/airflow/.local/lib/python3.6/site-packages/airflow/sensors/base.py", line 243, in execute
    time.sleep(self._get_next_poke_interval(started_at, run_duration, try_number))
  File "/home/airflow/.local/lib/python3.6/site-packages/airflow/models/taskinstance.py", line 1267, in signal_handler
    raise AirflowException("Task received SIGTERM signal")
airflow.exceptions.AirflowException: Task received SIGTERM signal
[2021-04-25 10:42:56,846] {taskinstance.py:1532} INFO - Marking task as UP_FOR_RETRY. dag_id=external_sensor_dag, task_id=external_sensor_task, execution_date=20210425T103242, start_date=20210425T103244, end_date=20210425T104256
[2021-04-25 10:42:56,969] {process_utils.py:66} INFO - Process psutil.Process(pid=73, status='terminated', exitcode=1, started='10:32:44') (73) terminated with exit code 1
