[2021-04-25 10:14:13,249] {taskinstance.py:877} INFO - Dependencies all met for <TaskInstance: file_sensor_dag.file_sensor_task 2021-04-25T10:14:11.897683+00:00 [queued]>
[2021-04-25 10:14:13,315] {taskinstance.py:877} INFO - Dependencies all met for <TaskInstance: file_sensor_dag.file_sensor_task 2021-04-25T10:14:11.897683+00:00 [queued]>
[2021-04-25 10:14:13,316] {taskinstance.py:1068} INFO - 
--------------------------------------------------------------------------------
[2021-04-25 10:14:13,316] {taskinstance.py:1069} INFO - Starting attempt 1 of 3
[2021-04-25 10:14:13,316] {taskinstance.py:1070} INFO - 
--------------------------------------------------------------------------------
[2021-04-25 10:14:13,361] {taskinstance.py:1089} INFO - Executing <Task(FileSensor): file_sensor_task> on 2021-04-25T10:14:11.897683+00:00
[2021-04-25 10:14:13,373] {standard_task_runner.py:52} INFO - Started process 57 to run task
[2021-04-25 10:14:13,394] {standard_task_runner.py:76} INFO - Running: ['airflow', 'tasks', 'run', 'file_sensor_dag', 'file_sensor_task', '2021-04-25T10:14:11.897683+00:00', '--job-id', '838', '--pool', 'default_pool', '--raw', '--subdir', 'DAGS_FOLDER/sensor/file_sensor.py', '--cfg-path', '/tmp/tmp4qsm3am4', '--error-file', '/tmp/tmpl97kp35z']
[2021-04-25 10:14:13,395] {standard_task_runner.py:77} INFO - Job 838: Subtask file_sensor_task
[2021-04-25 10:14:13,543] {logging_mixin.py:104} INFO - Running <TaskInstance: file_sensor_dag.file_sensor_task 2021-04-25T10:14:11.897683+00:00 [running]> on host d6e2455ef0ec
[2021-04-25 10:14:13,643] {taskinstance.py:1283} INFO - Exporting the following env vars:
AIRFLOW_CTX_DAG_OWNER=airflow
AIRFLOW_CTX_DAG_ID=file_sensor_dag
AIRFLOW_CTX_TASK_ID=file_sensor_task
AIRFLOW_CTX_EXECUTION_DATE=2021-04-25T10:14:11.897683+00:00
AIRFLOW_CTX_DAG_RUN_ID=manual__2021-04-25T10:14:11.897683+00:00
[2021-04-25 10:14:13,684] {taskinstance.py:1482} ERROR - Task failed with exception
Traceback (most recent call last):
  File "/home/airflow/.local/lib/python3.6/site-packages/airflow/models/taskinstance.py", line 1138, in _run_raw_task
    self._prepare_and_execute_task_with_callbacks(context, task)
  File "/home/airflow/.local/lib/python3.6/site-packages/airflow/models/taskinstance.py", line 1311, in _prepare_and_execute_task_with_callbacks
    result = self._execute_task(context, task_copy)
  File "/home/airflow/.local/lib/python3.6/site-packages/airflow/models/taskinstance.py", line 1341, in _execute_task
    result = task_copy.execute(context=context)
  File "/home/airflow/.local/lib/python3.6/site-packages/airflow/sensors/base.py", line 228, in execute
    while not self.poke(context):
  File "/home/airflow/.local/lib/python3.6/site-packages/airflow/sensors/filesystem.py", line 53, in poke
    hook = FSHook(self.fs_conn_id)
  File "/home/airflow/.local/lib/python3.6/site-packages/airflow/hooks/filesystem.py", line 38, in __init__
    conn = self.get_connection(conn_id)
  File "/home/airflow/.local/lib/python3.6/site-packages/airflow/hooks/base.py", line 67, in get_connection
    conn = Connection.get_connection_from_secrets(conn_id)
  File "/home/airflow/.local/lib/python3.6/site-packages/airflow/models/connection.py", line 354, in get_connection_from_secrets
    raise AirflowNotFoundException(f"The conn_id `{conn_id}` isn't defined")
airflow.exceptions.AirflowNotFoundException: The conn_id `fs_default` isn't defined
[2021-04-25 10:14:13,690] {taskinstance.py:1532} INFO - Marking task as UP_FOR_RETRY. dag_id=file_sensor_dag, task_id=file_sensor_task, execution_date=20210425T101411, start_date=20210425T101413, end_date=20210425T101413
[2021-04-25 10:14:13,811] {local_task_job.py:146} INFO - Task exited with return code 1
