[2021-04-25 13:43:24,470] {taskinstance.py:877} INFO - Dependencies all met for <TaskInstance: write_file_python_operator.write_execution_time_task 2021-04-25T13:34:00+00:00 [queued]>
[2021-04-25 13:43:24,494] {taskinstance.py:877} INFO - Dependencies all met for <TaskInstance: write_file_python_operator.write_execution_time_task 2021-04-25T13:34:00+00:00 [queued]>
[2021-04-25 13:43:24,494] {taskinstance.py:1068} INFO - 
--------------------------------------------------------------------------------
[2021-04-25 13:43:24,494] {taskinstance.py:1069} INFO - Starting attempt 2 of 3
[2021-04-25 13:43:24,495] {taskinstance.py:1070} INFO - 
--------------------------------------------------------------------------------
[2021-04-25 13:43:24,524] {taskinstance.py:1089} INFO - Executing <Task(PythonOperator): write_execution_time_task> on 2021-04-25T13:34:00+00:00
[2021-04-25 13:43:24,529] {standard_task_runner.py:52} INFO - Started process 66 to run task
[2021-04-25 13:43:24,540] {standard_task_runner.py:76} INFO - Running: ['airflow', 'tasks', 'run', 'write_file_python_operator', 'write_execution_time_task', '2021-04-25T13:34:00+00:00', '--job-id', '900', '--pool', 'default_pool', '--raw', '--subdir', 'DAGS_FOLDER/python_operator/write_file_python_operator.py', '--cfg-path', '/tmp/tmpukfl4l2m', '--error-file', '/tmp/tmpc1gz_3fk']
[2021-04-25 13:43:24,541] {standard_task_runner.py:77} INFO - Job 900: Subtask write_execution_time_task
[2021-04-25 13:43:24,638] {logging_mixin.py:104} INFO - Running <TaskInstance: write_file_python_operator.write_execution_time_task 2021-04-25T13:34:00+00:00 [running]> on host d6e2455ef0ec
[2021-04-25 13:43:24,699] {taskinstance.py:1283} INFO - Exporting the following env vars:
AIRFLOW_CTX_DAG_OWNER=airflow
AIRFLOW_CTX_DAG_ID=write_file_python_operator
AIRFLOW_CTX_TASK_ID=write_execution_time_task
AIRFLOW_CTX_EXECUTION_DATE=2021-04-25T13:34:00+00:00
AIRFLOW_CTX_DAG_RUN_ID=scheduled__2021-04-25T13:34:00+00:00
[2021-04-25 13:43:24,701] {taskinstance.py:1482} ERROR - Task failed with exception
Traceback (most recent call last):
  File "/home/airflow/.local/lib/python3.6/site-packages/airflow/models/taskinstance.py", line 1138, in _run_raw_task
    self._prepare_and_execute_task_with_callbacks(context, task)
  File "/home/airflow/.local/lib/python3.6/site-packages/airflow/models/taskinstance.py", line 1311, in _prepare_and_execute_task_with_callbacks
    result = self._execute_task(context, task_copy)
  File "/home/airflow/.local/lib/python3.6/site-packages/airflow/models/taskinstance.py", line 1341, in _execute_task
    result = task_copy.execute(context=context)
  File "/home/airflow/.local/lib/python3.6/site-packages/airflow/operators/python.py", line 117, in execute
    return_value = self.execute_callable()
  File "/home/airflow/.local/lib/python3.6/site-packages/airflow/operators/python.py", line 128, in execute_callable
    return self.python_callable(*self.op_args, **self.op_kwargs)
  File "/opt/airflow/dags/python_operator/write_file_python_operator.py", line 31, in fetch_and_write
    file.write(datetime.now())
TypeError: a bytes-like object is required, not 'datetime.datetime'
[2021-04-25 13:43:24,703] {taskinstance.py:1532} INFO - Marking task as UP_FOR_RETRY. dag_id=write_file_python_operator, task_id=write_execution_time_task, execution_date=20210425T133400, start_date=20210425T134324, end_date=20210425T134324
[2021-04-25 13:43:24,760] {local_task_job.py:146} INFO - Task exited with return code 1
